Workbook

Sheet Disclaimer
A1: Meridian Trust Bank – RHAIE Sizing Approximation
A3: This is a sizing approximation for Red Hat AI Enterprise on OpenShift. Numbers and suggestions here are based on approximation and estimates provided through the RHOAI Sizing Wizard app. For an actual sizing, a separate sizing workshop with Red Hat is recommended.
A8: This workbook is formula-driven: the Inputs, Reference and Models sheets hold literal values (yellow fill = editable); every other sheet computes from those cells with real Excel formulas. The live Step 5 dashboard in the wizard app uses the same assumptions for a quick preview, but this workbook — not the dashboard — is the canonical, auditable deliverable.
A13: Generated: 2026-10-02

Sheet Inputs
A1: Inputs — literal values entered in the wizard (yellow = editable)
A3: A. Customer & deployment
A4: Customer name | B4: Meridian Trust Bank
A5: Project name | B5: Meridian AI
A6: Deployment type | B6: production
A7: OpenShift version | B7: 4.21
A8: Network connectivity | B8: connected_proxy
A9: Deployment target | B9: on_prem_bare_metal
A10: Planning horizon (years) | B10: 3
A11: Annual growth rate | B11: 0.25
A12: Env: Production | B12: TRUE
A13: Env: Disaster recovery | B13: FALSE
A14: Env: Test / UAT | B14: TRUE
A15: Env: Development | B15: TRUE
A17: B. Hardware inventory
A18: Type | B18: GPU | C18: Count | D18: Form factor | E18: Servers
A19: Existing | B19: H200 NVL | C19: 8 | D19: HGX SXM 8-GPU | E19: 2
A20: Planned | B20: B300 | C20: 8 | D20: HGX SXM 8-GPU | E20: 1
A22: C. Platform configuration
A23: Number of data science projects | B23: 5
A24: Concurrent workbenches | B24: 5
A25: Workbench PVC size (GB) | B25: 50
A26: Concurrent training jobs | B26: 0
A27: Concurrent eval jobs | B27: 1
A28: Vector DB instances | B28: 1
A29: Concurrent pipeline runs | B29: 2
A30: Infra nodes per cluster | B30: 3
A31: Max CPU worker utilization (0-1) | B31: 0.8
A32: Model versions kept | B32: 2
A33: Prometheus retention (days) | B33: 15
A34: Loki retention (days) | B34: 90
A36: D. Enabled DataScienceCluster components
A37: Component | B37: Enabled
A38: Dashboard | B38: TRUE
A39: Workbenches | B39: TRUE
A40: AI Pipelines | B40: TRUE
A41: KServe (Model Serving) | B41: TRUE
A42: AI Gateway / MaaS (Models-as-a-Service) | B42: FALSE
A43: Kueue | B43: TRUE
A44: Ray (KubeRay) | B44: FALSE
...

Sheet Reference
A1: Reference — sourced constants (RHOAI 3.5 sizing workbook, OpenShift docs)
A3: A. GPU specifications
A4: GPU | B4: Memory (GB) | C4: HBM BW (TB/s) | D4: Dense FP4 PFLOPS | E4: Dense FP8 PFLOPS | F4: Dense BF16 PFLOPS | G4: Power (W) | H4: Form factor
A5: B300 | B5: 270 | C5: 8 | D5: 13.5 | E5: 4.5 | F5: 2.25 | G5: 1100 | H5: HGX SXM, 8 per node (NVL8)
A6: B200 | B6: 180 | C6: 8 | D6: 9 | E6: 4.5 | F6: 2.25 | G6: 1000 | H6: HGX SXM, 8 per node
A7: H200 NVL | B7: 141 | C7: 4.8 | D7: 0 | E7: 1.671 | F7: 0.836 | G7: 600 | H7: PCIe with NVLink bridge pairs (NVL2)
A8: H100 NVL | B8: 94 | C8: 3.9 | D8: 0 | E8: 1.671 | F8: 0.836 | G8: 400 | H8: PCIe with NVLink bridge pairs (NVL2)
A10: B. Control plane sizing tiers (by total worker node count, High scenario)
A11: Workers up to | B11: CPU cores | C11: Memory (GB) | D11: CPU cores (OVN-K) | E11: Memory GB (OVN-K)
A12: 24 | B12: 4 | C12: 16 | D12: 4 | E12: 16
A13: 120 | B13: 8 | C13: 32 | D13: 8 | E13: 32
A14: 252 | B14: 16 | C14: 64 | D14: 24 | E14: 128
A15: 501 | B15: 16 | C15: 96 | D15: 16 | E15: 96
A17: C. Infra node sizing tiers (by total worker node count, High scenario)
A18: Workers up to | B18: CPU cores | C18: Memory (GB)
A19: 27 | B19: 4 | C19: 24
A20: 120 | B20: 8 | C20: 48
A21: 252 | B21: 16 | C21: 128
A22: 501 | B22: 32 | C22: 128
A24: D. Non-GPU platform overhead line items (Cluster Architecture Table D)
A25: Key | B25: Label | C25: vCPU | D25: RAM (GiB) | E25: Gated by
A26: rhoai_controllers | B26: RHOAI controllers (Dashboard, KServe controller, Model Registry, MLflow) | C26: 4.18 | D26: 6.74 | E26: always
A27: openshift_platform_services | B27: OpenShift platform services (ingress, monitoring, logging/Loki, OADP) | C27: 8 | D27: 24 | E27: always
A28: node_feature_discovery_stack | B28: Node Feature Discovery, GPU Operator daemonsets, cert-manager, Connectivity Link, Authorino, Limitador | C28: 3 | D28: 6 | E28: anyGpu
A29: ai_gateway_and_dbs | B29: AI Gateway / MaaS + Model Registry/MLflow databases | C29: 3 | D29: 8 | E29: maas OR modelregistry OR mlflowoperator
A30: aipipelines_controller | B30: AI Pipelines controller (Kubeflow Pipelines + Argo Workflows) | C30: 4 | D30: 12 | E30: aipipelines
A31: cluster_observability_operator | B31: Cluster Observability Operator (llm-d dashboards) | C31: 2 | D31: 6 | E31: kserve
A32: kueue_controller | B32: Kueue controller | C32: 1.6 | D32: 2 | E32: kueue
A33: llmd_inference_scheduler_gateway | B33: llm-d inference scheduler + gateway (EPP + inference gateway) | C33: 4 | D33: 8 | E33: kserve
A35: E. Platform constants
A36: controlPlaneNodesPerCluster | B36: 3
A37: controlPlaneNodeMinVcpu | B37: 4
A38: controlPlaneNodeMinRamGB | B38: 16
A39: rhoaiInstallMinWorkerNodes | B39: 2
A40: rhoaiInstallMinVcpuPerWorker | B40: 8
A41: rhoaiInstallMinRamPerWorkerGiB | B41: 32
A42: rhoaiPlatformServicesPlanningAllowanceVcpu | B42: 16
A43: rhoaiPlatformServicesPlanningAllowanceRamGiB | B43: 64
A44: distributedWorkloadsControllersVcpu | B44: 1.6
A45: distributedWorkloadsControllersRamGiB | B45: 2
...

Sheet Models
A1: Models — captured from ConfigIQ (Step 2 Recommend/Predict results)
A3: Model | B3: Params (B) | C3: Active params (B) | D3: Precision | E3: GPU | F3: GPUs/replica | G3: TP size | H3: Replicas (ConfigIQ) | I3: GPUs (ConfigIQ) | J3: Weights (GB) | K3: KV cache/1K tok (GB) | L3: Max concurrent/replica | M3: TTFT est. (ms) | N3: TPOT (ms) | O3: Tokens/s | P3: Tokens/s/user | Q3: Mode | R3: Source | S3: Captured at
A4: Qwen/Qwen3.5-35B-A3B | E4: NVIDIA B300 SXM6 AC | F4: 1 | G4: 1 | H4: 1 | I4: 1 | J4: 64.558258 | K4: 176.39174 | L4: 16 | M4: 1115.6572 | N4: 8.4572852 | O4: 1776.8111 | P4: 133.44097 | Q4: agg | R4: recommend | S4: 2026-10-02T09:19:04.023Z
A5: Qwen/Qwen3-32B | E5: NVIDIA B300 SXM6 AC | F5: 1 | G5: 1 | H5: 1 | I5: 1 | J5: 61.022949 | K5: 182.21807 | L5: 1 | M5: 95.373514 | N5: 14.295773 | O5: 66.982856 | P5: 69.950745 | Q5: agg | R5: recommend | S5: 2026-10-02T10:41:49.611Z
A6: RedHatAI/gemma-4-26B-A4B-it-FP8-dynamic | E6: NVIDIA B300 SXM6 AC | F6: 1 | G6: 1 | H6: 1 | I6: 1 | J6: 48.374084 | K6: 194.68431 | L6: 1 | M6: 26.203096 | N6: 3.5767193 | O6: 266.41887 | P6: 279.58582 | Q6: agg | R6: recommend | S6: 2026-10-02T10:42:11.121Z

Sheet Sizing Summary
A1: RHOAI sizing approximation — Meridian Trust Bank
A2: Low: Low end of concurrent user range. High: High end of concurrent user range. Stress: Maximum concurrent users (see Workload Sizing sheet for the methodology).
A4: A. Headline numbers by scenario
A5: Metric | B5: Low | C5: High | D5: Stress | E5: Unit
A6: Total GPUs required | B6: =SUM('GPU Performance'!D4:'GPU Performance'!D4) | C6: =SUM('GPU Performance'!E4:'GPU Performance'!E4) | D6: =SUM('GPU Performance'!F4:'GPU Performance'!F4) | E6: GPUs
A7: Total cluster nodes | B7: ='Cluster Requirements'!B31 | C7: ='Cluster Requirements'!B32 | D7: ='Cluster Requirements'!B33 | E7: nodes
A8: CPU worker nodes | B8: ='Cluster Architecture'!B37 | C8: ='Cluster Architecture'!B37 | D8: ='Cluster Architecture'!B37 | E8: nodes
A9: Red Hat AI Enterprise subscriptions | B9: ='Cluster Architecture'!B37+SUM('GPU Performance'!G4:'GPU Performance'!G4) | C9: ='Cluster Architecture'!B37+SUM('GPU Performance'!H4:'GPU Performance'!H4) | D9: ='Cluster Architecture'!B37+SUM('GPU Performance'!I4:'GPU Performance'!I4) | E9: nodes
A11: B. Customer & deployment
A12: Customer | B12: ='Inputs'!B4
A13: Project | B13: ='Inputs'!B5
A14: Deployment type | B14: ='Inputs'!B6
A15: OpenShift version | B15: ='Inputs'!B7
A16: Connectivity | B16: ='Inputs'!B8
A17: Target | B17: ='Inputs'!B9
A18: Planning horizon (years) | B18: ='Inputs'!B10
A19: Annual growth rate | B19: ='Inputs'!B11
A21: C. Storage totals
A22: Object storage | B22: ='Cluster Architecture'!B50 | C22: GiB
A23: Block storage | B23: ='Cluster Architecture'!B51 | C23: GiB
A24: GPU-node local NVMe | B24: ='Cluster Architecture'!B52 | C24: GB
A26: D. Checks before you quote
A27: Status | B27: Check | C27: Detail
A28: WARN | B28: Use cases not mapped to a sized model | C28: 2 use case(s) are excluded from GPU sizing because they aren't mapped to a model in Step 3: Customer support chatbot, Compliance document reviewer. Map them to a sized model or they won't be counted.
A29: =IF(AND('Models'!L5<=2,'Workload Sizing'!F19>=5),"WARN","OK") | B29: Qwen/Qwen3-32B: replica count vs. captured per-replica concurrency | C29: =IF(AND('Models'!L5<=2,'Workload Sizing'!F19>=5),"Captured per-replica concurrency is only "&'Models'!L5&" (from Step 2 Target concurrency), driving "&'Workload Sizing'!F19&" replicas at High demand. If one replica can realistically serve more than "&'Models'!L5&" request(s) at once, raise Target concurrency in Step 2 to that batch size and re-add the model.","Replica count looks consistent with its captured per-replica concurrency.")
A30: OK | B30: NVIDIA B300 SXM6 AC host RAM rule (>= host RAM multiplier × total GPU memory per node) | C30: ="Plan for >= "&('Reference'!B60*'GPU Performance'!B4*'GPU Performance'!C4)&" GiB host RAM per NVIDIA B300 SXM6 AC node ("&'GPU Performance'!C4&" GPUs x "&'GPU Performance'!B4&" GB x "&'Reference'!B60&")."
A31: OK | B31: NVIDIA B300 SXM6 AC physical cores rule | C31: ="Plan for >= "&'Reference'!B61&" physical cores per GPU (NVIDIA-Certified floor), >= "&'Reference'!B62&" recommended."
A32: =IF('Cluster Architecture'!B37>='Reference'!B39,"OK","WARN") | B32: CPU worker node minimum (RHOAI install requirement) | C32: ='Cluster Architecture'!B37&" CPU worker node(s) planned; RHOAI requires >= "&'Reference'!B39&" workers at >= "&'Reference'!B40&" vCPU / "&'Reference'!B41&" GiB each."
A33: =IF('Cluster Architecture'!B37>1,"OK","WARN") | B33: N-1 capacity (one CPU worker node can fail) | C33: =IF('Cluster Architecture'!B37>1,('Cluster Architecture'!B37-1)&" node(s) of capacity still covers CPU demand if sized with headroom.","Only one CPU worker node planned — no failure tolerance. Add a second node for production.")

Sheet Workload Sizing
A1: Meridian Trust Bank — use cases, models and GPU demand
A3: A. Model deployments (from ConfigIQ Step 2 — see Models sheet)
A4: Model | B4: GPU | C4: GPUs/replica | D4: TP size | E4: Weights (GB) | F4: KV cache/1K tok (GB) | G4: Max concurrent/replica | H4: TTFT est. (ms) | I4: Tokens/s | J4: Precision
A5: ='Models'!A4 | B5: ='Models'!E4 | C5: ='Models'!F4 | D5: ='Models'!G4 | E5: ='Models'!J4 | F5: ='Models'!K4 | G5: ='Models'!L4 | H5: ='Models'!M4 | I5: ='Models'!O4 | J5: ='Models'!D4
A6: ='Models'!A5 | B6: ='Models'!E5 | C6: ='Models'!F5 | D6: ='Models'!G5 | E6: ='Models'!J5 | F6: ='Models'!K5 | G6: ='Models'!L5 | H6: ='Models'!M5 | I6: ='Models'!O5 | J6: ='Models'!D5
A7: ='Models'!A6 | B7: ='Models'!E6 | C7: ='Models'!F6 | D7: ='Models'!G6 | E7: ='Models'!J6 | F7: ='Models'!K6 | G7: ='Models'!L6 | H7: ='Models'!M6 | I7: ='Models'!O6 | J7: ='Models'!D6
A9: B. Use cases — edit values on the Inputs sheet, section F
A10: Use case | B10: Served by model | C10: Users — Low | D10: Users — High | E10: Share in flight | F10: Input tokens | G10: Output tokens | H10: Prefix cache hit rate | I10: TTFT target (s) | J10: Tokens/s target | K10: Guard screened | L10: Notes
A11: ='Inputs'!A66 | B11: ='Inputs'!B66 | C11: ='Inputs'!C66 | D11: ='Inputs'!D66 | E11: ='Inputs'!E66 | F11: ='Inputs'!F66 | G11: ='Inputs'!G66 | H11: ='Inputs'!H66 | ... K11: ='Inputs'!K66 | L11: ='Inputs'!M66
A12: ='Inputs'!A67 | B12: ='Inputs'!B67 | C12: ='Inputs'!C67 | D12: ='Inputs'!D67 | E12: ='Inputs'!E67 | F12: ='Inputs'!F67 | G12: ='Inputs'!G67 | H12: ='Inputs'!H67 | ... K12: ='Inputs'!K67 | L12: ='Inputs'!M67
A13: ='Inputs'!A68 | B13: ='Inputs'!B68 | C13: ='Inputs'!C68 | D13: ='Inputs'!D68 | E13: ='Inputs'!E68 | F13: ='Inputs'!F68 | G13: ='Inputs'!G68 | H13: ='Inputs'!H68 | ... K13: ='Inputs'!K68 | L13: ='Inputs'!M68
A15: C. Load per model deployment (Low / High / Stress)
A16: Stress methodology: every High-estimate user is treated as having a request in flight at once (ignores Share in flight — that factor is used only for the Low/High columns). Click a Stress cell below vs. a Low/High cell in the same row to see the formula difference.
A17: Model | B17: Requests in flight — Low | C17: Requests in flight — High | D17: Requests in flight — Stress | E17: Replicas — Low | F17: Replicas — High | G17: Replicas — Stress | H17: GPUs — Low | I17: GPUs — High | J17: GPUs — Stress
A18: ='Models'!A4 | B18: 0 | C18: 0 | D18: 0 | E18: ='Models'!H4 | F18: ='Models'!H4 | G18: ='Models'!H4 | H18: ='Models'!I4 | I18: ='Models'!I4 | J18: ='Models'!I4
A19: ='Models'!A5 | B19: ='Inputs'!C66*'Inputs'!E66 | C19: ='Inputs'!D66*'Inputs'!E66 | D19: ='Inputs'!D66 | E19: =MAX('Models'!H5,ROUNDUP(B19/MAX(1,'Models'!L5),0)) | F19: =MAX('Models'!H5,ROUNDUP(C19/MAX(1,'Models'!L5),0)) | G19: =MAX('Models'!H5,ROUNDUP(D19/MAX(1,'Models'!L5),0)) | H19: =E19*'Models'!F5 | I19: =F19*'Models'!F5 | J19: =G19*'Models'!F5
A20: ='Models'!A6 | B20: 0 | C20: 0 | D20: 0 | E20: ='Models'!H6 | F20: ='Models'!H6 | G20: ='Models'!H6 | H20: ='Models'!I6 | I20: ='Models'!I6 | J20: ='Models'!I6

Sheet GPU Performance
A1: GPU performance and node demand by GPU type
A3: GPU | B3: GPU memory (GB) | C3: GPUs/node | D3: GPUs required — Low | E3: GPUs required — High | F3: GPUs required — Stress | G3: Nodes required — Low | H3: Nodes required — High | I3: Nodes required — Stress
A4: NVIDIA B300 SXM6 AC | B4: ='Reference'!B5 | C4: 8 | D4: ='Workload Sizing'!H18+'Workload Sizing'!H19+'Workload Sizing'!H20 | E4: ='Workload Sizing'!I18+'Workload Sizing'!I19+'Workload Sizing'!I20 | F4: ='Workload Sizing'!J18+'Workload Sizing'!J19+'Workload Sizing'!J20 | G4: =IF(D4=0,0,MAX(2,ROUNDUP(D4/C4,0))) | H4: =IF(E4=0,0,MAX(2,ROUNDUP(E4/C4,0))) | I4: =IF(F4=0,0,MAX(2,ROUNDUP(F4/C4,0)))

Sheet Cluster Architecture
A1: Meridian Trust Bank — target cluster architecture
A3: A. Non-GPU platform overhead build-up (Table D)
A4: Each row is gated on whether its parent component is enabled on the Inputs sheet (section D) — toggle a component there and this table recalculates.
A5: Line item | B5: Applies? | C5: vCPU | D5: RAM (GiB)
A6: ='Reference'!B26 | B6: =TRUE | C6: =IF(B6,'Reference'!C26,0) | D6: =IF(B6,'Reference'!D26,0)
A7: ='Reference'!B27 | B7: =TRUE | C7: =IF(B7,'Reference'!C27,0) | D7: =IF(B7,'Reference'!D27,0)
A8: ='Reference'!B28 | B8: =OR(SUM(Inputs!C19:C20)>0,3>0) | C8: =IF(B8,'Reference'!C28,0) | D8: =IF(B8,'Reference'!D28,0)
A9: ='Reference'!B29 | B9: =OR('Inputs'!B42,'Inputs'!B48,'Inputs'!B50) | C9: =IF(B9,'Reference'!C29,0) | D9: =IF(B9,'Reference'!D29,0)
A10: ='Reference'!B30 | B10: =OR('Inputs'!B40) | C10: =ROUND(IF(B10,'Reference'!C30+MAX(0,'Inputs'!B29-1)*1,0),2) | D10: =ROUND(IF(B10,'Reference'!D30+MAX(0,'Inputs'!B29-1)*3,0),2)
A11: ='Reference'!B31 | B11: =OR('Inputs'!B41) | C11: =IF(B11,'Reference'!C31,0) | D11: =IF(B11,'Reference'!D31,0)
A12: ='Reference'!B32 | B12: =OR('Inputs'!B43) | C12: =IF(B12,'Reference'!C32,0) | D12: =IF(B12,'Reference'!D32,0)
A13: ='Reference'!B33 | B13: =OR('Inputs'!B41) | C13: =IF(B13,'Reference'!C33,0) | D13: =IF(B13,'Reference'!D33,0)
A14: Subtotal — platform overhead line items | C14: =ROUND(SUM(C6:C13),2) | D14: =ROUND(SUM(D6:D13),2)
A16: B. Dynamic non-GPU demand (scales with wizard inputs)
A17: Item | B17: vCPU | C17: RAM (GiB) | D17: Basis
A18: Distributed workloads controllers (Kueue/Ray/Trainer) | B18: =IF(OR('Inputs'!B43,'Inputs'!B44,'Inputs'!B45),'Reference'!B44,0) | C18: =IF(OR('Inputs'!B43,'Inputs'!B44,'Inputs'!B45),'Reference'!B45,0) | D18: On if Kueue, Ray, or Trainer is enabled
A19: Workbenches (Medium profile, 8 vCPU / 16 GiB each) | B19: ='Inputs'!B24*8 | C19: ='Inputs'!B24*16 | D19: Concurrent workbenches × Medium profile
A20: Training jobs (CPU-side footprint only; GPUs counted separately) | B20: ='Inputs'!B26*8 | C20: ='Inputs'!B26*64 | D20: Concurrent training jobs × LoRA-class footprint
A21: Evaluation jobs | B21: ='Inputs'!B27*4 | C21: ='Inputs'!B27*16 | D21: Concurrent eval jobs
A22: Vector DB instances | B22: ='Inputs'!B28*4 | C22: ='Inputs'!B28*16 | D22: Vector DB instances
A23: Per-project: Pipeline server | B23: =ROUND(IF('Inputs'!B56,1*'Inputs'!B23*0.5,0),2) | C23: =ROUND(IF('Inputs'!B56,1*'Inputs'!B23*1,0),2) | D23: 1/project × projects, if enabled
A24: Per-project: MLflow server | B24: =ROUND(IF('Inputs'!B57,1*'Inputs'!B23*0.5,0),2) | C24: =ROUND(IF('Inputs'!B57,1*'Inputs'!B23*1,0),2) | D24: 1/project × projects, if enabled
A25: Per-project: OGX server | B25: =ROUND(IF('Inputs'!B58,1*'Inputs'!B23*0.25,0),2) | C25: =ROUND(IF('Inputs'!B58,1*'Inputs'!B23*0.488,0),2) | D25: 1/project × projects, if enabled
A26: Per-project: PostgreSQL for OGX | B26: =ROUND(IF('Inputs'!B59,1*'Inputs'!B23*0.5,0),2) | C26: =ROUND(IF('Inputs'!B59,1*'Inputs'!B23*1,0),2) | D26: 1/project × projects, if enabled
A27: Per-project: Model registry instance | B27: =ROUND(IF('Inputs'!B60,0.1*'Inputs'!B23*0.5,0),2) | C27: =ROUND(IF('Inputs'!B60,0.1*'Inputs'!B23*1,0),2) | D27: 0.1/project × projects, if enabled
A28: Per-project: TrustyAI / guardrails per project | B28: =ROUND(IF('Inputs'!B61,1*'Inputs'!B23*0.5,0),2) | C28: =ROUND(IF('Inputs'!B61,1*'Inputs'!B23*1,0),2) | D28: 1/project × projects, if enabled
A29: Per-project: EvalHub per-tenant instance | B29: =ROUND(IF('Inputs'!B62,1*'Inputs'!B23*0.5,0),2) | C29: =ROUND(IF('Inputs'!B62,1*'Inputs'!B23*1,0),2) | D29: 1/project × projects, if enabled
A30: Sized-model sidecars (oauth-proxy etc.) | B30: =ROUND(3*'Reference'!B48,2) | C30: =ROUND(3*'Reference'!B49,2) | D30: 3 sized model(s) × per-model sidecar
A31: Subtotal — dynamic non-GPU demand | B31: =ROUND(SUM(B18:B30),2) | C31: =ROUND(SUM(C18:C30),2)
A33: C. Total non-GPU (CPU worker) demand
A34: Metric | B34: Value | C34: Unit
A35: CPU worker vCPU demand | B35: =ROUND(C14+B31,2) | C35: vCPU
A36: CPU worker RAM demand | B36: =ROUND(D14+C31,2) | C36: GiB
A37: CPU worker nodes (computed) | B37: =MAX('Reference'!B39,ROUNDUP(B35/(16*'Inputs'!B31),0),ROUNDUP(B36/(64*'Inputs'!B31),0)) | C37: nodes
A39: Total worker nodes (High) — used to pick control-plane/infra tiers | B39: =B37+SUM('GPU Performance'!H4:'GPU Performance'!H4)
A41: D. Node pools
A42: Role | B42: Count | C42: vCPU/node | D42: RAM (GB)/node
A43: Control plane | B43: ='Reference'!B36 | C43: =IFS(B39<='Reference'!A12,'Reference'!B12,B39<='Reference'!A13,'Reference'!B13,B39<='Reference'!A14,'Reference'!B14,TRUE,'Reference'!B15) | D43: =IFS(B39<='Reference'!A12,'Reference'!C12,B39<='Reference'!A13,'Reference'!C13,B39<='Reference'!A14,'Reference'!C14,TRUE,'Reference'!C15)
A44: Infra | B44: ='Inputs'!B30 | C44: =IFS(B39<='Reference'!A19,'Reference'!B19,B39<='Reference'!A20,'Reference'!B20,B39<='Reference'!A21,'Reference'!B21,TRUE,'Reference'!B22) | D44: =IFS(B39<='Reference'!A19,'Reference'!C19,B39<='Reference'!A20,'Reference'!C20,B39<='Reference'!A21,'Reference'!C21,TRUE,'Reference'!C22)
A45: CPU worker | B45: =B37 | C45: 16 | D45: 64
...

Sheet Cluster Requirements
A1: Minimum cluster requirements and component dependencies
A3: A. Platform inputs
A4: OpenShift version | B4: ='Inputs'!B7
A5: Target cluster type | B5: ='Inputs'!B9
A6: Network connectivity | B6: ='Inputs'!B8
A7: Number of data science projects | B7: ='Inputs'!B23
A8: Concurrent workbenches | B8: ='Inputs'!B24
A9: Infra nodes per cluster | B9: ='Inputs'!B30
A11: B. DataScienceCluster components
A12: Component | B12: Enabled | C12: Status | D12: Database | E12: Prerequisites
A13: Dashboard | B13: ='Inputs'!B38 | C13: GA
A14: Workbenches | B14: ='Inputs'!B39 | C14: GA
A15: AI Pipelines | B15: ='Inputs'!B40 | C15: GA | D15: MariaDB/MySQL | E15: S3-compatible object storage
A16: KServe (Model Serving) | B16: ='Inputs'!B41 | C16: GA | E16: cert-manager
A17: AI Gateway / MaaS (Models-as-a-Service) | B17: ='Inputs'!B42 | C17: Technology Preview | D17: PostgreSQL (gateway policy/usage store) | E17: Red Hat Connectivity Link
A18: Kueue | B18: ='Inputs'!B43 | C18: GA | E18: Red Hat build of Kueue Operator, cert-manager
A19: Ray (KubeRay) | B19: ='Inputs'!B44 | C19: GA | E19: Red Hat build of Kueue Operator, cert-manager
A20: Kubeflow Trainer v2 | B20: ='Inputs'!B45 | C20: GA | E20: JobSet Operator
A21: Kubeflow Training Operator v1 | B21: ='Inputs'!B46 | C21: Deprecated | E21: Red Hat build of Kueue Operator, cert-manager
A22: Feature Store (Feast) | B22: ='Inputs'!B47 | C22: GA | D22: Redis/Valkey or PostgreSQL
A23: Model Registry | B23: ='Inputs'!B48 | C23: GA | D23: MySQL 5.x+/8.x or PostgreSQL (in-cluster default: 5Gi PVC)
A24: TrustyAI / Guardrails / EvalHub | B24: ='Inputs'!B49 | C24: GA | D24: PostgreSQL
A25: MLflow | B25: ='Inputs'!B50 | C25: GA | D25: PostgreSQL (SQLite for dev/test only) | E25: PostgreSQL, S3 (trace archival)
A26: OGX (formerly Llama Stack) | B26: ='Inputs'!B51 | C26: GA | D26: PostgreSQL (required for production; SQLite dev/test only) | E26: OGX Operator, cert-manager, NFD, NVIDIA GPU Operator, S3 object storage, PostgreSQL Operator
A27: MCP Lifecycle Operator | B27: ='Inputs'!B52 | C27: Technology Preview
A29: C. Node count summary
A30: Scenario | B30: Total nodes
A31: Low | B31: ='Reference'!B36+'Inputs'!B30+'Cluster Architecture'!B37+SUM('GPU Performance'!G4:'GPU Performance'!G4)
A32: High | B32: ='Reference'!B36+'Inputs'!B30+'Cluster Architecture'!B37+SUM('GPU Performance'!H4:'GPU Performance'!H4)
A33: Stress | B33: ='Reference'!B36+'Inputs'!B30+'Cluster Architecture'!B37+SUM('GPU Performance'!I4:'GPU Performance'!I4)

Sheet Red Hat Subscriptions
A1: Meridian Trust Bank — Red Hat subscription bill of materials
A2: Red Hat AI Enterprise is counted per node, physical or virtual, for GPU and CPU worker nodes alike, regardless of the number of GPUs in a node.
A4: SKU | B4: Description | C4: Qty (Low) | D4: Qty (High) | E4: Qty (Stress) | F4: Remarks
A5: MCT4990 | B5: Red Hat AI Enterprise, Premium (1 Physical or Virtual Node) | C5: ='Cluster Architecture'!B37+SUM('GPU Performance'!G4:'GPU Performance'!G4) | D5: ='Cluster Architecture'!B37+SUM('GPU Performance'!H4:'GPU Performance'!H4) | E5: ='Cluster Architecture'!B37+SUM('GPU Performance'!I4:'GPU Performance'!I4) | F5: Counts GPU worker nodes + CPU worker nodes across all enabled environments.

Sheet Hardware BOM
A1: Meridian Trust Bank — hardware bill of materials
A3: Node type | B3: GPU | C3: GPUs/node | D3: Nodes (Low) | E3: Nodes (High) | F3: Nodes (Stress)
A4: gpu-nvidia-b300-sxm6-ac | B4: ='GPU Performance'!A4 | C4: ='GPU Performance'!C4 | D4: ='GPU Performance'!G4 | E4: ='GPU Performance'!H4 | F4: ='GPU Performance'!I4
A5: cpu-worker | B5: — | C5: — | D5: ='Cluster Architecture'!B37 | E5: ='Cluster Architecture'!B37 | F5: ='Cluster Architecture'!B37
A6: control-plane | B6: — | C6: — | D6: ='Reference'!B36 | E6: ='Reference'!B36 | F6: ='Reference'!B36
A7: infra | B7: — | C7: — | D7: ='Inputs'!B30 | E7: ='Inputs'!B30 | F7: ='Inputs'!B30

Sheet Backup and DR
A1: Meridian Trust Bank — backup and disaster recovery
A3: Environments configured
A4: Environment | B4: Included
A5: Production | B5: =IF('Inputs'!B12,"Yes","No")
A6: Disaster recovery | B6: =IF('Inputs'!B13,"Yes","No")
A7: Test / UAT | B7: =IF('Inputs'!B14,"Yes","No")
A8: Development | B8: =IF('Inputs'!B15,"Yes","No")
A10: Recommended protection mechanisms
A11: - Model artifacts: object storage geo-replication (asynchronous) to the DR site.
A12: - Model Registry, MLflow and pipelines metadata: PostgreSQL streaming replication to DR.
A13: - Workbench PVs and shared datasets: storage-level snapshot/mirroring on a 5-minute schedule.
A14: - Cluster and RHOAI configuration: GitOps (Argo CD) + OADP backup of RHOAI namespaces.
A15: - etcd: scheduled snapshot to object storage.

Sheet Model Catalog
A1: Selected models (sized via ConfigIQ) — see Models sheet for the literal captured values
A3: Model | B3: Params (B) | C3: Active params (B) | D3: Precision | E3: GPU | F3: GPUs/replica | G3: Replicas (ConfigIQ default) | H3: Weights (GB) | I3: KV cache/1K tok (GB) | J3: Captured at
A4: ='Models'!A4 | B4: ='Models'!B4 | C4: ='Models'!C4 | D4: ='Models'!D4 | E4: ='Models'!E4 | F4: ='Models'!F4 | G4: ='Models'!H4 | H4: ='Models'!J4 | I4: ='Models'!K4 | J4: ='Models'!S4
A5: ='Models'!A5 | B5: ='Models'!B5 | C5: ='Models'!C5 | D5: ='Models'!D5 | E5: ='Models'!E5 | F5: ='Models'!F5 | G5: ='Models'!H5 | H5: ='Models'!J5 | I5: ='Models'!K5 | J5: ='Models'!S5
A6: ='Models'!A6 | B6: ='Models'!B6 | C6: ='Models'!C6 | D6: ='Models'!D6 | E6: ='Models'!E6 | F6: ='Models'!F6 | G6: ='Models'!H6 | H6: ='Models'!J6 | I6: ='Models'!K6 | J6: ='Models'!S6
